<?xml version="1.0" encoding="utf-8"?>
<!-- This URDF was automatically created by SolidWorks to URDF Exporter! Originally created by Stephen Brawner (brawner@gmail.com) 
     Commit Version: 1.6.0-4-g7f85cfe  Build Version: 1.6.7995.38578
     For more information, please see http://wiki.ros.org/sw_urdf_exporter -->
<robot
  name="CM_HL_v8">
  <link
    name="base_link">
    <inertial>
      <origin
        xyz="0.079147034347242 0.000256543804017355 0.000435548775883074"
        rpy="0 0 0" />
      <mass
        value="0.0166778103679292" />
      <inertia
        ixx="1.46638258492931E-05"
        ixy="1.90183148822614E-09"
        ixz="3.68488235881721E-10"
        iyy="7.16031019539989E-06"
        iyz="-4.3543995749257E-08"
        izz="7.51790795790666E-06" />
    </inertial>
    <visual>
      <origin
        xyz="0 0 0"
        rpy="0 0 0" />
      <geometry>
        <mesh
          filename="package://CM_HL_v8/meshes/base_link.STL" />
      </geometry>
      <material
        name="">
        <color
          rgba="0.894117647058823 0.894117647058823 0.894117647058823 1" />
      </material>
    </visual>
    <collision>
      <origin
        xyz="0 0 0"
        rpy="0 0 0" />
      <geometry>
        <mesh
          filename="package://CM_HL_v8/meshes/base_link.STL" />
      </geometry>
    </collision>
  </link>
  <link
    name="HL_link2_thigh_r">
    <inertial>
      <origin
        xyz="0.0199957134741563 -0.0387726556940942 -0.000170134594790525"
        rpy="0 0 0" />
      <mass
        value="0.0392091866021753" />
      <inertia
        ixx="2.29078530952156E-05"
        ixy="-9.40088287932107E-09"
        ixz="-4.45868024964848E-07"
        iyy="4.06585481198753E-05"
        iyz="-5.4665397253342E-08"
        izz="2.37194865231989E-05" />
    </inertial>
    <visual>
      <origin
        xyz="0 0 0"
        rpy="0 0 0" />
      <geometry>
        <mesh
          filename="package://CM_HL_v8/meshes/HL_link2_thigh_r.STL" />
      </geometry>
      <material
        name="">
        <color
          rgba="0.223529411764706 0.223529411764706 0.223529411764706 1" />
      </material>
    </visual>
    <collision>
      <origin
        xyz="0 0 0"
        rpy="0 0 0" />
      <geometry>
        <mesh
          filename="package://CM_HL_v8/meshes/HL_link2_thigh_r.STL" />
      </geometry>
    </collision>
  </link>
  <joint
    name="HL_joint2_thigh_r"
    type="revolute">
    <origin
      xyz="0 0 0"
      rpy="0 0 0" />
    <parent
      link="base_link" />
    <child
      link="HL_link2_thigh_r" />
    <axis
      xyz="-1 0 0" />
    <limit
      lower="-3.14"
      upper="3.14"
      effort="100"
      velocity="0" />
  </joint>
  <link
    name="HL_link3_thigh_p">
    <inertial>
      <origin
        xyz="-0.0603282418668271 -0.0199078023804649 -0.0762642203724724"
        rpy="0 0 0" />
      <mass
        value="0.115410236451442" />
      <inertia
        ixx="0.000223812173465736"
        ixy="9.69380124023684E-08"
        ixz="-9.64538764909021E-05"
        iyy="0.000345887112245255"
        iyz="1.43580558480981E-07"
        izz="0.00012464524632718" />
    </inertial>
    <visual>
      <origin
        xyz="0 0 0"
        rpy="0 0 0" />
      <geometry>
        <mesh
          filename="package://CM_HL_v8/meshes/HL_link3_thigh_p.STL" />
      </geometry>
      <material
        name="">
        <color
          rgba="0.894117647058823 0.894117647058823 0.894117647058823 1" />
      </material>
    </visual>
    <collision>
      <origin
        xyz="0 0 0"
        rpy="0 0 0" />
      <geometry>
        <mesh
          filename="package://CM_HL_v8/meshes/HL_link3_thigh_p.STL" />
      </geometry>
    </collision>
  </link>
  <joint
    name="HL_joint3_thigh_p"
    type="revolute">
    <origin
      xyz="0 0 0"
      rpy="0 0 0" />
    <parent
      link="HL_link2_thigh_r" />
    <child
      link="HL_link3_thigh_p" />
    <axis
      xyz="0 1 0" />
    <limit
      lower="-3.14"
      upper="3.14"
      effort="100"
      velocity="0" />
  </joint>
  <link
    name="HL_link4_knee_p">
    <inertial>
      <origin
        xyz="0.0672316863132475 -0.00429574969821129 -0.0411999833706305"
        rpy="0 0 0" />
      <mass
        value="0.126150884922169" />
      <inertia
        ixx="0.000154424144181571"
        ixy="-1.1783426165149E-06"
        ixz="0.000172260725720491"
        iyy="0.000486223969288729"
        iyz="5.48278372175068E-07"
        izz="0.000334693769655284" />
    </inertial>
    <visual>
      <origin
        xyz="0 0 0"
        rpy="0 0 0" />
      <geometry>
        <mesh
          filename="package://CM_HL_v8/meshes/HL_link4_knee_p.STL" />
      </geometry>
      <material
        name="">
        <color
          rgba="0.894117647058823 0.894117647058823 0.894117647058823 1" />
      </material>
    </visual>
    <collision>
      <origin
        xyz="0 0 0"
        rpy="0 0 0" />
      <geometry>
        <mesh
          filename="package://CM_HL_v8/meshes/HL_link4_knee_p.STL" />
      </geometry>
    </collision>
  </link>
  <joint
    name="HL_joint4_knee_p"
    type="revolute">
    <origin
      xyz="-0.105 -0.004 -0.18187"
      rpy="0 0 0" />
    <parent
      link="HL_link3_thigh_p" />
    <child
      link="HL_link4_knee_p" />
    <axis
      xyz="0 1 0" />
    <limit
      lower="-3.14"
      upper="3.14"
      effort="100"
      velocity="0" />
  </joint>
  <link
    name="HL_link5_ankle_p">
    <inertial>
      <origin
        xyz="-0.0208378663520434 0.0003114349045425 -0.0494616512372393"
        rpy="0 0 0" />
      <mass
        value="0.090814526434762" />
      <inertia
        ixx="0.000129272186316712"
        ixy="-9.37894899726077E-09"
        ixz="-8.58721453593097E-05"
        iyy="0.00019796827083096"
        iyz="7.24495545989856E-09"
        izz="7.04316711173481E-05" />
    </inertial>
    <visual>
      <origin
        xyz="0 0 0"
        rpy="0 0 0" />
      <geometry>
        <mesh
          filename="package://CM_HL_v8/meshes/HL_link5_ankle_p.STL" />
      </geometry>
      <material
        name="">
        <color
          rgba="0.894117647058823 0.894117647058823 0.894117647058823 1" />
      </material>
    </visual>
    <collision>
      <origin
        xyz="0 0 0"
        rpy="0 0 0" />
      <geometry>
        <mesh
          filename="package://CM_HL_v8/meshes/HL_link5_ankle_p.STL" />
      </geometry>
    </collision>
  </link>
  <joint
    name="HL_joint5_ankle_p"
    type="revolute">
    <origin
      xyz="0.18187 -0.0035 -0.105"
      rpy="0 0 0" />
    <parent
      link="HL_link4_knee_p" />
    <child
      link="HL_link5_ankle_p" />
    <axis
      xyz="0 1 0" />
    <limit
      lower="-3.14"
      upper="3.14"
      effort="100"
      velocity="0" />
  </joint>
  <link
    name="HL_link6_toe_p">
    <inertial>
      <origin
        xyz="-0.0205541894626347 5.08872277533408E-05 -0.000853746825219104"
        rpy="0 0 0" />
      <mass
        value="0.0392139289733728" />
      <inertia
        ixx="9.84407361555167E-06"
        ixy="9.80698424431825E-13"
        ixz="-6.12847391019406E-07"
        iyy="8.84697022702377E-06"
        iyz="-6.97280742181781E-12"
        izz="1.55193417810945E-05" />
    </inertial>
    <visual>
      <origin
        xyz="0 0 0"
        rpy="0 0 0" />
      <geometry>
        <mesh
          filename="package://CM_HL_v8/meshes/HL_link6_toe_p.STL" />
      </geometry>
      <material
        name="">
        <color
          rgba="0.894117647058823 0.894117647058823 0.894117647058823 1" />
      </material>
    </visual>
    <collision>
      <origin
        xyz="0 0 0"
        rpy="0 0 0" />
      <geometry>
        <mesh
          filename="package://CM_HL_v8/meshes/HL_link6_toe_p.STL" />
      </geometry>
    </collision>
  </link>
  <joint
    name="HL_joint6_toe_p"
    type="revolute">
    <origin
      xyz="-0.074 0 -0.12817"
      rpy="0 0 0" />
    <parent
      link="HL_link5_ankle_p" />
    <child
      link="HL_link6_toe_p" />
    <axis
      xyz="0 1 0" />
    <limit
      lower="-3.14"
      upper="3.14"
      effort="100"
      velocity="0" />
  </joint>
</robot>